<? xml version="1.0" ?>
<robot name="three_wheel_robot">
  <!-- Base link -->
  <link name="base_link">
    <visual>
      <geometry>
        <box size="0.5 0.5 0.1"/> 
      </geometry>
      <material name="grey"/>
    </visual>
  </link>
  <!-- Wheels -->
  <link name="wheel_front">
    <visual>
      <geometry>
        <cylinder radius="0.1" length="0.05"/>
      </geometry>
      <material name="black"/>
    </visual>
  </link>
  <link name="wheel_left">
    <visual>
      <geometry>
        <cylinder radius="0.1" length="0.05"/>
      </geometry>
      <material name="black"/>
    </visual>
  </link>
  <link name="wheel_right">
    <visual>
      <geometry>
        <cylinder radius="0.1" length="0.05"/>
      </geometry>
      <material name="black"/>
    </visual>
  </link>
  <!-- Joints -->
  <joint name="joint_front_wheel" type="continuous">
    <parent link="base_link"/>
    <child link="wheel_front"/>
    <origin xyz="0 0.25 0" rpy="0 0 0"/>
    <axis xyz="0 0 1"/>
  </joint>
  <joint name="joint_left_wheel" type="continuous">
    <parent link="base_link"/>
    <child link="wheel_left"/>
    <origin xyz="-0.25 -0.25 0" rpy="0 0 0"/>
    <axis xyz="0 0 1"/>
  </joint>
  <joint name="joint_right_wheel" type="continuous">
    <parent link="base_link"/>
    <child link="wheel_right"/>
    <origin xyz="0.25 -0.25 0" rpy="0 0 0"/>
    <axis xyz="0 0 1"/>
  </joint>
  <!-- Sensors -->
  <gazebo>
    <sensor type="camera" name="camera">
      <update_rate>30</update_rate>
      <camera>
        <horizontal_fov>1.3962634</horizontal_fov>
        <image>
          <width>800</width>
          <height>800</height>
        </image>
      </camera>
      <plugin name="camera_controller" filename="libgazebo_ros_camera.so">
        <always_on>true</always_on>
        <update_rate>30</update_rate>
        <camera_name>camera</camera_name>
      </plugin>
    </sensor>
  </gazebo>
</robot>

